<?xml version="1.0" encoding="utf-8"?>
<!-- This URDF was automatically created by SolidWorks to URDF Exporter! Originally created by Stephen Brawner (brawner@gmail.com) 
     Commit Version: 1.6.0-4-g7f85cfe  Build Version: 1.6.7995.38578
     For more information, please see http://wiki.ros.org/sw_urdf_exporter -->
<robot
  name="spyder">
  <link
    name="base_link">
    <inertial>
      <origin
        xyz="3.3307E-16 -9.5132E-15 -0.0025"
        rpy="0 0 0" />
      <mass
        value="0.088858" />
      <inertia
        ixx="0.00011246"
        ixy="-1.4773E-20"
        ixz="-9.5488E-20"
        iyy="0.00017229"
        iyz="-1.4021E-20"
        izz="0.00028438" />
    </inertial>
    <visual>
      <origin
        xyz="0 0 0"
        rpy="0 0 0" />
      <geometry>
        <mesh
          filename="package://spyder/meshes/base_link.STL" />
      </geometry>
      <material
        name="PLA">
        <color
          rgba="0.79216 0.81961 0.93333 1" />
      </material>
    </visual>
    <collision>
      <origin
        xyz="0 0 0"
        rpy="0 0 0" />
      <geometry>
        <mesh
          filename="package://spyder/meshes/base_link.STL" />
      </geometry>
    </collision>
  </link>
  <link
    name="hip_RB_link">
    <inertial>
      <origin
        xyz="-0.00025475 0.031162 0.031073"
        rpy="0 0 0" />
      <mass
        value="0.032853" />
      <inertia
        ixx="1.704E-05"
        ixy="-2.4444E-07"
        ixz="-2.49E-09"
        iyy="2.2641E-05"
        iyz="1.5339E-07"
        izz="1.7054E-05" />
    </inertial>
    <visual>
      <origin
        xyz="0 0 0"
        rpy="0 0 0" />
      <geometry>
        <mesh
          filename="package://spyder/meshes/hip_RB_link.STL" />
      </geometry>
      <material
        name="PLA">
        <color
          rgba="0.79216 0.81961 0.93333 1" />
      </material>
    </visual>
    <collision>
      <origin
        xyz="0 0 0"
        rpy="0 0 0" />
      <geometry>
        <mesh
          filename="package://spyder/meshes/hip_RB_link.STL" />
      </geometry>
    </collision>
  </link>
  <joint
    name="hip_RB_joint"
    type="revolute">
    <origin
      xyz="-0.0528 0.065 0.014"
      rpy="3.1416 0 3.1416" />
    <parent
      link="base_link" />
    <child
      link="hip_RB_link" />
    <axis
      xyz="0 0 1" />
    <limit
      lower="-1.57"
      upper="1.57"
      effort="0.922"
      velocity="6.16" />
  </joint>
  <link
    name="knee_RB_link">
    <inertial>
      <origin
        xyz="0.03519 0.038386 0.041687"
        rpy="0 0 0" />
      <mass
        value="0.062595" />
      <inertia
        ixx="3.5399E-05"
        ixy="-2.3801E-05"
        ixz="-1.3249E-20"
        iyy="3.1256E-05"
        iyz="-1.4786E-20"
        izz="5.7615E-05" />
    </inertial>
    <visual>
      <origin
        xyz="0 0 0"
        rpy="0 0 0" />
      <geometry>
        <mesh
          filename="package://spyder/meshes/knee_RB_link.STL" />
      </geometry>
      <material
        name="PLA">
        <color
          rgba="0.79216 0.81961 0.93333 1" />
      </material>
    </visual>
    <collision>
      <origin
        xyz="0 0 0"
        rpy="0 0 0" />
      <geometry>
        <mesh
          filename="package://spyder/meshes/knee_RB_link.STL" />
      </geometry>
    </collision>
  </link>
  <joint
    name="knee_RB_joint"
    type="revolute">
    <origin
      xyz="-0.032535 0.06348 0.0315"
      rpy="0.016231 1.5708 0" />
    <parent
      link="hip_RB_link" />
    <child
      link="knee_RB_link" />
    <axis
      xyz="0 0 1" />
    <limit
      lower="-1.57"
      upper="1.57"
      effort="0.922"
      velocity="6.16" />
  </joint>
  <link
    name="ankle_RB_link">
    <inertial>
      <origin
        xyz="-0.091638 0.027064 0.031328"
        rpy="0 0 0" />
      <mass
        value="0.081055" />
      <inertia
        ixx="5.052E-05"
        ixy="4.5682E-05"
        ixz="-1.4972E-07"
        iyy="0.00018353"
        iyz="4.3099E-08"
        izz="0.00016991" />
    </inertial>
    <visual>
      <origin
        xyz="0 0 0"
        rpy="0 0 0" />
      <geometry>
        <mesh
          filename="package://spyder/meshes/ankle_RB_link.STL" />
      </geometry>
      <material
        name="PLA">
        <color
          rgba="0.79216 0.81961 0.93333 1" />
      </material>
    </visual>
    <collision>
      <origin
        xyz="0 0 0"
        rpy="0 0 0" />
      <geometry>
        <mesh
          filename="package://spyder/meshes/ankle_RB_link.STL" />
      </geometry>
    </collision>
  </link>
  <joint
    name="ankle_RB_joint"
    type="revolute">
    <origin
      xyz="0.07136 0.077841 0"
      rpy="0 0 0" />
    <parent
      link="knee_RB_link" />
    <child
      link="ankle_RB_link" />
    <axis
      xyz="0 0 1" />
    <limit
      lower="-1.57"
      upper="1.57"
      effort="0.922"
      velocity="6.16" />
  </joint>
  <link
    name="hip_RF_link">
    <inertial>
      <origin
        xyz="0.00043179 0.03116 0.031073"
        rpy="0 0 0" />
      <mass
        value="0.032853" />
      <inertia
        ixx="1.7032E-05"
        ixy="-1.2084E-07"
        ixz="8.8973E-10"
        iyy="2.2649E-05"
        iyz="1.5341E-07"
        izz="1.7054E-05" />
    </inertial>
    <visual>
      <origin
        xyz="0 0 0"
        rpy="0 0 0" />
      <geometry>
        <mesh
          filename="package://spyder/meshes/hip_RF_link.STL" />
      </geometry>
      <material
        name="PLA">
        <color
          rgba="0.79216 0.81961 0.93333 1" />
      </material>
    </visual>
    <collision>
      <origin
        xyz="0 0 0"
        rpy="0 0 0" />
      <geometry>
        <mesh
          filename="package://spyder/meshes/hip_RF_link.STL" />
      </geometry>
    </collision>
  </link>
  <joint
    name="hip_RF_joint"
    type="revolute">
    <origin
      xyz="0.0528000000000004 0.0649999999999906 0.014"
      rpy="3.14159265358979 0 3.14159265358979" />
    <parent
      link="base_link" />
    <child
      link="hip_RF_link" />
    <axis
      xyz="0 0 1" />
    <limit
      lower="-1.57"
      upper="1.57"
      effort="0.922"
      velocity="6.16" />
  </joint>
  <link
    name="knee_RF_link">
    <inertial>
      <origin
        xyz="0.038535 0.035025 0.041687"
        rpy="0 0 0" />
      <mass
        value="0.062595" />
      <inertia
        ixx="3.1052E-05"
        ixy="-2.3782E-05"
        ixz="-7.4257E-20"
        iyy="3.5602E-05"
        iyz="-6.7396E-20"
        izz="5.7615E-05" />
    </inertial>
    <visual>
      <origin
        xyz="0 0 0"
        rpy="0 0 0" />
      <geometry>
        <mesh
          filename="package://spyder/meshes/knee_RF_link.STL" />
      </geometry>
      <material
        name="PLA">
        <color
          rgba="0.79216 0.81961 0.93333 1" />
      </material>
    </visual>
    <collision>
      <origin
        xyz="0 0 0"
        rpy="0 0 0" />
      <geometry>
        <mesh
          filename="package://spyder/meshes/knee_RF_link.STL" />
      </geometry>
    </collision>
  </link>
  <joint
    name="knee_RF_joint"
    type="revolute">
    <origin
      xyz="-0.031128 0.064182 0.0315"
      rpy="0.0057996 1.5708 0" />
    <parent
      link="hip_RF_link" />
    <child
      link="knee_RF_link" />
    <axis
      xyz="0 0 1" />
    <limit
      lower="-1.57"
      upper="1.57"
      effort="0.922"
      velocity="6.16" />
  </joint>
  <link
    name="ankle_RF_link">
    <inertial>
      <origin
        xyz="-0.08502 0.043606 0.031328"
        rpy="0 0 0" />
      <mass
        value="0.081055" />
      <inertia
        ixx="7.1771E-05"
        ixy="6.6796E-05"
        ixz="-1.3911E-07"
        iyy="0.00016227"
        iyz="7.0145E-08"
        izz="0.00016991" />
    </inertial>
    <visual>
      <origin
        xyz="0 0 0"
        rpy="0 0 0" />
      <geometry>
        <mesh
          filename="package://spyder/meshes/ankle_RF_link.STL" />
      </geometry>
      <material
        name="PLA">
        <color
          rgba="0.79216 0.81961 0.93333 1" />
      </material>
    </visual>
    <collision>
      <origin
        xyz="0 0 0"
        rpy="0 0 0" />
      <geometry>
        <mesh
          filename="package://spyder/meshes/ankle_RF_link.STL" />
      </geometry>
    </collision>
  </link>
  <joint
    name="ankle_RF_joint"
    type="revolute">
    <origin
      xyz="0.078145 0.071027 0"
      rpy="0 0 0" />
    <parent
      link="knee_RF_link" />
    <child
      link="ankle_RF_link" />
    <axis
      xyz="0 0 1" />
    <limit
      lower="-1.57"
      upper="1.57"
      effort="0.922"
      velocity="6.16" />
  </joint>
  <link
    name="hip_LB_link">
    <inertial>
      <origin
        xyz="-0.00018488 0.031163 0.031073"
        rpy="0 0 0" />
      <mass
        value="0.032853" />
      <inertia
        ixx="1.7039E-05"
        ixy="-2.3188E-07"
        ixz="-2.146E-09"
        iyy="2.2642E-05"
        iyz="1.534E-07"
        izz="1.7054E-05" />
    </inertial>
    <visual>
      <origin
        xyz="0 0 0"
        rpy="0 0 0" />
      <geometry>
        <mesh
          filename="package://spyder/meshes/hip_LB_link.STL" />
      </geometry>
      <material
        name="PLA">
        <color
          rgba="0.79216 0.81961 0.93333 1" />
      </material>
    </visual>
    <collision>
      <origin
        xyz="0 0 0"
        rpy="0 0 0" />
      <geometry>
        <mesh
          filename="package://spyder/meshes/hip_LB_link.STL" />
      </geometry>
    </collision>
  </link>
  <joint
    name="hip_LB_joint"
    type="revolute">
    <origin
      xyz="-0.0528 -0.065 0.014"
      rpy="3.1416 0 0" />
    <parent
      link="base_link" />
    <child
      link="hip_LB_link" />
    <axis
      xyz="0 0 1" />
    <limit
      lower="-1.57"
      upper="1.57"
      effort="0.922"
      velocity="6.16" />
  </joint>
  <link
    name="knee_LB_link">
    <inertial>
      <origin
        xyz="0.03006 0.042522 0.041687"
        rpy="0 0 0" />
      <mass
        value="0.062595" />
      <inertia
        ixx="4.1296E-05"
        ixy="-2.2523E-05"
        ixz="-5.8024E-21"
        iyy="2.5359E-05"
        iyz="-7.1725E-21"
        izz="5.7615E-05" />
    </inertial>
    <visual>
      <origin
        xyz="0 0 0"
        rpy="0 0 0" />
      <geometry>
        <mesh
          filename="package://spyder/meshes/knee_LB_link.STL" />
      </geometry>
      <material
        name="PLA">
        <color
          rgba="0.79216 0.81961 0.93333 1" />
      </material>
    </visual>
    <collision>
      <origin
        xyz="0 0 0"
        rpy="0 0 0" />
      <geometry>
        <mesh
          filename="package://spyder/meshes/knee_LB_link.STL" />
      </geometry>
    </collision>
  </link>
  <joint
    name="knee_LB_joint"
    type="revolute">
    <origin
      xyz="-0.032392 0.063553 0.0315"
      rpy="3.1276 1.5708 3.1416" />
    <parent
      link="hip_LB_link" />
    <child
      link="knee_LB_link" />
    <axis
      xyz="0 0 1" />
    <limit
      lower="-1.57"
      upper="1.57"
      effort="0.922"
      velocity="6.16" />
  </joint>
  <link
    name="ankle_LB_link">
    <inertial>
      <origin
        xyz="-0.091638 0.027064 0.031328"
        rpy="0 0 0" />
      <mass
        value="0.081055" />
      <inertia
        ixx="5.052E-05"
        ixy="4.5682E-05"
        ixz="-1.4972E-07"
        iyy="0.00018353"
        iyz="4.3099E-08"
        izz="0.00016991" />
    </inertial>
    <visual>
      <origin
        xyz="0 0 0"
        rpy="0 0 0" />
      <geometry>
        <mesh
          filename="package://spyder/meshes/ankle_LB_link.STL" />
      </geometry>
      <material
        name="PLA">
        <color
          rgba="0.79216 0.81961 0.93333 1" />
      </material>
    </visual>
    <collision>
      <origin
        xyz="0 0 0"
        rpy="0 0 0" />
      <geometry>
        <mesh
          filename="package://spyder/meshes/ankle_LB_link.STL" />
      </geometry>
    </collision>
  </link>
  <joint
    name="ankle_LB_joint"
    type="revolute">
    <origin
      xyz="0.060958 0.086229 0"
      rpy="0 0 0" />
    <parent
      link="knee_LB_link" />
    <child
      link="ankle_LB_link" />
    <axis
      xyz="0 0 1" />
    <limit
      lower="-1.57"
      upper="1.57"
      effort="0.922"
      velocity="6.16" />
  </joint>
  <link
    name="hip_LF_link">
    <inertial>
      <origin
        xyz="0.0029804 0.03102 0.031073"
        rpy="0 0 0" />
      <mass
        value="0.032853" />
      <inertia
        ixx="1.705E-05"
        ixy="3.3895E-07"
        ixz="1.3441E-08"
        iyy="2.2631E-05"
        iyz="1.5282E-07"
        izz="1.7054E-05" />
    </inertial>
    <visual>
      <origin
        xyz="0 0 0"
        rpy="0 0 0" />
      <geometry>
        <mesh
          filename="package://spyder/meshes/hip_LF_link.STL" />
      </geometry>
      <material
        name="PLA">
        <color
          rgba="0.79216 0.81961 0.93333 1" />
      </material>
    </visual>
    <collision>
      <origin
        xyz="0 0 0"
        rpy="0 0 0" />
      <geometry>
        <mesh
          filename="package://spyder/meshes/hip_LF_link.STL" />
      </geometry>
    </collision>
  </link>
  <joint
    name="hip_LF_joint"
    type="revolute">
    <origin
      xyz="0.0528 -0.065 0.014"
      rpy="3.1416 0 0" />
    <parent
      link="base_link" />
    <child
      link="hip_LF_link" />
    <axis
      xyz="0 0 1" />
    <limit
      lower="-1.57"
      upper="1.57"
      effort="0.922"
      velocity="6.16" />
  </joint>
  <link
    name="knee_LF_link">
    <inertial>
      <origin
        xyz="0.051669 0.0064834 0.041687"
        rpy="0 0 0" />
      <mass
        value="0.062595" />
      <inertia
        ixx="1.0177E-05"
        ixy="-5.9027E-06"
        ixz="-9.5643E-20"
        iyy="5.6478E-05"
        iyz="-1.2966E-20"
        izz="5.7615E-05" />
    </inertial>
    <visual>
      <origin
        xyz="0 0 0"
        rpy="0 0 0" />
      <geometry>
        <mesh
          filename="package://spyder/meshes/knee_LF_link.STL" />
      </geometry>
      <material
        name="PLA">
        <color
          rgba="0.79216 0.81961 0.93333 1" />
      </material>
    </visual>
    <collision>
      <origin
        xyz="0 0 0"
        rpy="0 0 0" />
      <geometry>
        <mesh
          filename="package://spyder/meshes/knee_LF_link.STL" />
      </geometry>
    </collision>
  </link>
  <joint
    name="knee_LF_joint"
    type="revolute">
    <origin
      xyz="-0.025771 0.066514 0.0315"
      rpy="0.087728 1.5708 0" />
    <parent
      link="hip_LF_link" />
    <child
      link="knee_LF_link" />
    <axis
      xyz="0 0 -1" />
    <limit
      lower="-1.57"
      upper="1.57"
      effort="0.922"
      velocity="6.16" />
  </joint>
  <link
    name="ankle_LF_link">
    <inertial>
      <origin
        xyz="-0.067225 0.067902 0.031328"
        rpy="0 0 0" />
      <mass
        value="0.081055" />
      <inertia
        ixx="0.00012005"
        ixy="8.0624E-05"
        ixz="-1.1037E-07"
        iyy="0.00011399"
        iyz="1.0996E-07"
        izz="0.00016991" />
    </inertial>
    <visual>
      <origin
        xyz="0 0 0"
        rpy="0 0 0" />
      <geometry>
        <mesh
          filename="package://spyder/meshes/ankle_LF_link.STL" />
      </geometry>
      <material
        name="">
        <color
          rgba="0.79216 0.81961 0.93333 1" />
      </material>
    </visual>
    <collision>
      <origin
        xyz="0 0 0"
        rpy="0 0 0" />
      <geometry>
        <mesh
          filename="package://spyder/meshes/ankle_LF_link.STL" />
      </geometry>
    </collision>
  </link>
  <joint
    name="ankle_LF_joint"
    type="revolute">
    <origin
      xyz="0.10478 0.013147 0"
      rpy="0 0 0" />
    <parent
      link="knee_LF_link" />
    <child
      link="ankle_LF_link" />
    <axis
      xyz="0 0 1" />
    <limit
      lower="-1.57"
      upper="1.57"
      effort="0.922"
      velocity="6.16" />
  </joint>
</robot>