<?xml version="1.0" encoding="utf-8"?>
<!-- This URDF was automatically created by SolidWorks to URDF Exporter! Originally created by Stephen Brawner (brawner@gmail.com) 
     Commit Version: 1.6.0-4-g7f85cfe  Build Version: 1.6.7995.38578
     For more information, please see http://wiki.ros.org/sw_urdf_exporter -->
<robot
  name="spider">
  <link
    name="base_link">
    <inertial>
      <origin
        xyz="3.9496E-14 2.609E-15 -0.022569"
        rpy="0 0 0" />
      <mass
        value="0.37198" />
      <inertia
        ixx="0.00058404"
        ixy="1.3343E-12"
        ixz="-1.0835E-19"
        iyy="0.00048578"
        iyz="4.4752E-20"
        izz="0.0010268" />
    </inertial>
    <visual>
      <origin
        xyz="0 0 0"
        rpy="0 0 0" />
      <geometry>
        <mesh
          filename="package://spider/meshes/base_link.STL" />
      </geometry>
      <material
        name="PLA">
        <color
          rgba="0.79216 0.81961 0.93333 1" />
      </material>
    </visual>
    <collision>
      <origin
        xyz="0 0 0"
        rpy="0 0 0" />
      <geometry>
        <mesh
          filename="package://spider/meshes/base_link.STL" />
      </geometry>
    </collision>
  </link>
  <link
    name="hip_RB_link">
    <inertial>
      <origin
        xyz="0.00049208 0.031159 0.031073"
        rpy="0 0 0" />
      <mass
        value="0.032853" />
      <inertia
        ixx="1.7031E-05"
        ixy="-1.0997E-07"
        ixz="1.1866E-09"
        iyy="2.265E-05"
        iyz="1.5341E-07"
        izz="1.7054E-05" />
    </inertial>
    <visual>
      <origin
        xyz="0 0 0"
        rpy="0 0 0" />
      <geometry>
        <mesh
          filename="package://spider/meshes/hip_RB_link.STL" />
      </geometry>
      <material
        name="PLA">
        <color
          rgba="0.79216 0.81961 0.93333 1" />
      </material>
    </visual>
    <collision>
      <origin
        xyz="0 0 0"
        rpy="0 0 0" />
      <geometry>
        <mesh
          filename="package://spider/meshes/hip_RB_link.STL" />
      </geometry>
    </collision>
  </link>
  <joint
    name="hip_RB_joint"
    type="revolute">
    <origin
      xyz="-0.0528 0.065 0.014"
      rpy="3.1416 0 3.1416" />
    <parent
      link="base_link" />
    <child
      link="hip_RB_link" />
    <axis
      xyz="0 0 1" />
    <limit
      lower="-1.57"
      upper="1.57"
      effort="0.922"
      velocity="6.16" />
  </joint>
  <link
    name="knee_RB_link">
    <inertial>
      <origin
        xyz="0.052429 0.00095949 0.035953"
        rpy="0 0 0" />
      <mass
        value="0.12554" />
      <inertia
        ixx="1.8824E-05"
        ixy="-9.9371E-07"
        ixz="5.6055E-18"
        iyy="7.3105E-05"
        iyz="-1.2525E-16"
        izz="6.8262E-05" />
    </inertial>
    <visual>
      <origin
        xyz="0 0 0"
        rpy="0 0 0" />
      <geometry>
        <mesh
          filename="package://spider/meshes/knee_RB_link.STL" />
      </geometry>
      <material
        name="PLA">
        <color
          rgba="0.79216 0.81961 0.93333 1" />
      </material>
    </visual>
    <collision>
      <origin
        xyz="0 0 0"
        rpy="0 0 0" />
      <geometry>
        <mesh
          filename="package://spider/meshes/knee_RB_link.STL" />
      </geometry>
    </collision>
  </link>
  <joint
    name="knee_RB_joint"
    type="revolute">
    <origin
      xyz="-0.031004 0.064242 0.0315"
      rpy="0.0077348 1.5708 0" />
    <parent
      link="hip_RB_link" />
    <child
      link="knee_RB_link" />
    <axis
      xyz="0 0 1" />
    <limit
      lower="-1.57"
      upper="1.57"
      effort="0.922"
      velocity="6.16" />
  </joint>
  <link
    name="ankle_RB_link">
    <inertial>
      <origin
        xyz="-0.088054 0.0371 0.031328"
        rpy="0 0 0" />
      <mass
        value="0.081055" />
      <inertia
        ixx="6.228E-05"
        ixy="5.9268E-05"
        ixz="-1.4399E-07"
        iyy="0.00017177"
        iyz="5.9503E-08"
        izz="0.00016991" />
    </inertial>
    <visual>
      <origin
        xyz="0 0 0"
        rpy="0 0 0" />
      <geometry>
        <mesh
          filename="package://spider/meshes/ankle_RB_link.STL" />
      </geometry>
      <material
        name="PLA">
        <color
          rgba="0.79216 0.81961 0.93333 1" />
      </material>
    </visual>
    <collision>
      <origin
        xyz="0 0 0"
        rpy="0 0 0" />
      <geometry>
        <mesh
          filename="package://spider/meshes/ankle_RB_link.STL" />
      </geometry>
    </collision>
  </link>
  <joint
    name="ankle_RB_joint"
    type="revolute">
    <origin
      xyz="0.10558 0.0019322 0"
      rpy="0 0 0" />
    <parent
      link="knee_RB_link" />
    <child
      link="ankle_RB_link" />
    <axis
      xyz="0 0 1" />
    <limit
      lower="-1.57"
      upper="1.57"
      effort="0.922"
      velocity="6.16" />
  </joint>
  <link
    name="hip_RF_link">
    <inertial>
      <origin
        xyz="-1.2819E-05 0.031163 0.031073"
        rpy="0 0 0" />
      <mass
        value="0.032853" />
      <inertia
        ixx="1.7036E-05"
        ixy="-2.0093E-07"
        ixz="-1.299E-09"
        iyy="2.2645E-05"
        iyz="1.5341E-07"
        izz="1.7054E-05" />
    </inertial>
    <visual>
      <origin
        xyz="0 0 0"
        rpy="0 0 0" />
      <geometry>
        <mesh
          filename="package://spider/meshes/hip_RF_link.STL" />
      </geometry>
      <material
        name="PLA">
        <color
          rgba="0.79216 0.81961 0.93333 1" />
      </material>
    </visual>
    <collision>
      <origin
        xyz="0 0 0"
        rpy="0 0 0" />
      <geometry>
        <mesh
          filename="package://spider/meshes/hip_RF_link.STL" />
      </geometry>
    </collision>
  </link>
  <joint
    name="hip_RF_joint"
    type="revolute">
    <origin
      xyz="0.0528 0.065 0.014"
      rpy="3.1416 0 3.1416" />
    <parent
      link="base_link" />
    <child
      link="hip_RF_link" />
    <axis
      xyz="0 0 1" />
    <limit
      lower="-1.57"
      upper="1.57"
      effort="0.922"
      velocity="6.16" />
  </joint>
  <link
    name="knee_RF_link">
    <inertial>
      <origin
        xyz="0.052431 0.00085755 0.035953"
        rpy="0 0 0" />
      <mass
        value="0.12554" />
      <inertia
        ixx="1.882E-05"
        ixy="-8.8817E-07"
        ixz="-3.8276E-18"
        iyy="7.3109E-05"
        iyz="1.1281E-16"
        izz="6.8262E-05" />
    </inertial>
    <visual>
      <origin
        xyz="0 0 0"
        rpy="0 0 0" />
      <geometry>
        <mesh
          filename="package://spider/meshes/knee_RF_link.STL" />
      </geometry>
      <material
        name="PLA">
        <color
          rgba="0.79216 0.81961 0.93333 1" />
      </material>
    </visual>
    <collision>
      <origin
        xyz="0 0 0"
        rpy="0 0 0" />
      <geometry>
        <mesh
          filename="package://spider/meshes/knee_RF_link.STL" />
      </geometry>
    </collision>
  </link>
  <joint
    name="knee_RF_joint"
    type="revolute">
    <origin
      xyz="-0.032041 0.063731 0.0315"
      rpy="0.0084678 1.5708 0" />
    <parent
      link="hip_RF_link" />
    <child
      link="knee_RF_link" />
    <axis
      xyz="0 0 1" />
    <limit
      lower="-1.57"
      upper="1.57"
      effort="0.922"
      velocity="6.16" />
  </joint>
  <link
    name="ankle_RF_link">
    <inertial>
      <origin
        xyz="-0.088026 0.037166 0.031328"
        rpy="0 0 0" />
      <mass
        value="0.081055" />
      <inertia
        ixx="6.2369E-05"
        ixy="5.935E-05"
        ixz="-1.4394E-07"
        iyy="0.00017168"
        iyz="5.9611E-08"
        izz="0.00016991" />
    </inertial>
    <visual>
      <origin
        xyz="0 0 0"
        rpy="0 0 0" />
      <geometry>
        <mesh
          filename="package://spider/meshes/ankle_RF_link.STL" />
      </geometry>
      <material
        name="PLA">
        <color
          rgba="0.79216 0.81961 0.93333 1" />
      </material>
    </visual>
    <collision>
      <origin
        xyz="0 0 0"
        rpy="0 0 0" />
      <geometry>
        <mesh
          filename="package://spider/meshes/ankle_RF_link.STL" />
      </geometry>
    </collision>
  </link>
  <joint
    name="ankle_RF_joint"
    type="revolute">
    <origin
      xyz="0.10559 0.0017269 0"
      rpy="0 0 0" />
    <parent
      link="knee_RF_link" />
    <child
      link="ankle_RF_link" />
    <axis
      xyz="0 0 1" />
    <limit
      lower="-1.57"
      upper="1.57"
      effort="0.922"
      velocity="6.16" />
  </joint>
  <link
    name="hip_LB_link">
    <inertial>
      <origin
        xyz="-0.00018488 0.031163 0.031073"
        rpy="0 0 0" />
      <mass
        value="0.032853" />
      <inertia
        ixx="1.7039E-05"
        ixy="-2.3188E-07"
        ixz="-2.146E-09"
        iyy="2.2642E-05"
        iyz="1.534E-07"
        izz="1.7054E-05" />
    </inertial>
    <visual>
      <origin
        xyz="0 0 0"
        rpy="0 0 0" />
      <geometry>
        <mesh
          filename="package://spider/meshes/hip_LB_link.STL" />
      </geometry>
      <material
        name="PLA">
        <color
          rgba="0.79216 0.81961 0.93333 1" />
      </material>
    </visual>
    <collision>
      <origin
        xyz="0 0 0"
        rpy="0 0 0" />
      <geometry>
        <mesh
          filename="package://spider/meshes/hip_LB_link.STL" />
      </geometry>
    </collision>
  </link>
  <joint
    name="hip_LB_joint"
    type="revolute">
    <origin
      xyz="-0.0528 -0.065 0.014"
      rpy="3.1416 0 0" />
    <parent
      link="base_link" />
    <child
      link="hip_LB_link" />
    <axis
      xyz="0 0 1" />
    <limit
      lower="-1.57"
      upper="1.57"
      effort="0.922"
      velocity="6.16" />
  </joint>
  <link
    name="knee_LB_link">
    <inertial>
      <origin
        xyz="0.052437 0.00032122 0.035953"
        rpy="0 0 0" />
      <mass
        value="0.12554" />
      <inertia
        ixx="1.8808E-05"
        ixy="-3.3272E-07"
        ixz="9.6567E-20"
        iyy="7.3122E-05"
        iyz="5.44E-17"
        izz="6.8262E-05" />
    </inertial>
    <visual>
      <origin
        xyz="0 0 0"
        rpy="0 0 0" />
      <geometry>
        <mesh
          filename="package://spider/meshes/knee_LB_link.STL" />
      </geometry>
      <material
        name="PLA">
        <color
          rgba="0.79216 0.81961 0.93333 1" />
      </material>
    </visual>
    <collision>
      <origin
        xyz="0 0 0"
        rpy="0 0 0" />
      <geometry>
        <mesh
          filename="package://spider/meshes/knee_LB_link.STL" />
      </geometry>
    </collision>
  </link>
  <joint
    name="knee_LB_joint"
    type="revolute">
    <origin
      xyz="-0.032392 0.063553 0.0315"
      rpy="0.013989 1.5708 0" />
    <parent
      link="hip_LB_link" />
    <child
      link="knee_LB_link" />
    <axis
      xyz="0 0 1" />
    <limit
      lower="-1.57"
      upper="1.57"
      effort="0.922"
      velocity="6.16" />
  </joint>
  <link
    name="ankle_LB_link">
    <inertial>
      <origin
        xyz="-0.086202 0.04122 0.031328"
        rpy="0 0 0" />
      <mass
        value="0.081055" />
      <inertia
        ixx="6.812E-05"
        ixy="6.4172E-05"
        ixz="-1.4101E-07"
        iyy="0.00016593"
        iyz="6.6241E-08"
        izz="0.00016991" />
    </inertial>
    <visual>
      <origin
        xyz="0 0 0"
        rpy="0 0 0" />
      <geometry>
        <mesh
          filename="package://spider/meshes/ankle_LB_link.STL" />
      </geometry>
      <material
        name="PLA">
        <color
          rgba="0.79216 0.81961 0.93333 1" />
      </material>
    </visual>
    <collision>
      <origin
        xyz="0 0 0"
        rpy="0 0 0" />
      <geometry>
        <mesh
          filename="package://spider/meshes/ankle_LB_link.STL" />
      </geometry>
    </collision>
  </link>
  <joint
    name="ankle_LB_joint"
    type="revolute">
    <origin
      xyz="0.1056 0.00064686 0"
      rpy="0 0 0" />
    <parent
      link="knee_LB_link" />
    <child
      link="ankle_LB_link" />
    <axis
      xyz="0 0 1" />
    <limit
      lower="-1.57"
      upper="1.57"
      effort="0.922"
      velocity="6.16" />
  </joint>
  <link
    name="hip_LF_link">
    <inertial>
      <origin
        xyz="-0.0002804 0.031162 0.031073"
        rpy="0 0 0" />
      <mass
        value="0.032853" />
      <inertia
        ixx="1.704E-05"
        ixy="-2.4905E-07"
        ixz="-2.6162E-09"
        iyy="2.2641E-05"
        iyz="1.5339E-07"
        izz="1.7054E-05" />
    </inertial>
    <visual>
      <origin
        xyz="0 0 0"
        rpy="0 0 0" />
      <geometry>
        <mesh
          filename="package://spider/meshes/hip_LF_link.STL" />
      </geometry>
      <material
        name="PLA">
        <color
          rgba="0.79216 0.81961 0.93333 1" />
      </material>
    </visual>
    <collision>
      <origin
        xyz="0 0 0"
        rpy="0 0 0" />
      <geometry>
        <mesh
          filename="package://spider/meshes/hip_LF_link.STL" />
      </geometry>
    </collision>
  </link>
  <joint
    name="hip_LF_joint"
    type="revolute">
    <origin
      xyz="0.0528 -0.065 0.014"
      rpy="3.1416 0 0" />
    <parent
      link="base_link" />
    <child
      link="hip_LF_link" />
    <axis
      xyz="0 0 1" />
    <limit
      lower="-1.57"
      upper="1.57"
      effort="0.922"
      velocity="6.16" />
  </joint>
  <link
    name="knee_LF_link">
    <inertial>
      <origin
        xyz="0.052437 0.00038896 0.035953"
        rpy="0 0 0" />
      <mass
        value="0.12554" />
      <inertia
        ixx="1.8809E-05"
        ixy="-4.0289E-07"
        ixz="1.4422E-19"
        iyy="7.3121E-05"
        iyz="5.8217E-17"
        izz="6.8262E-05" />
    </inertial>
    <visual>
      <origin
        xyz="0 0 0"
        rpy="0 0 0" />
      <geometry>
        <mesh
          filename="package://spider/meshes/knee_LF_link.STL" />
      </geometry>
      <material
        name="PLA">
        <color
          rgba="0.79216 0.81961 0.93333 1" />
      </material>
    </visual>
    <collision>
      <origin
        xyz="0 0 0"
        rpy="0 0 0" />
      <geometry>
        <mesh
          filename="package://spider/meshes/knee_LF_link.STL" />
      </geometry>
    </collision>
  </link>
  <joint
    name="knee_LF_joint"
    type="revolute">
    <origin
      xyz="-0.032587 0.063454 0.0315"
      rpy="0.017054 1.5708 0" />
    <parent
      link="hip_LF_link" />
    <child
      link="knee_LF_link" />
    <axis
      xyz="0 0 -1" />
    <limit
      lower="-1.57"
      upper="1.57"
      effort="0.922"
      velocity="6.16" />
  </joint>
  <link
    name="ankle_LF_link">
    <inertial>
      <origin
        xyz="-0.085981 0.04168 0.031328"
        rpy="0 0 0" />
      <mass
        value="0.081055" />
      <inertia
        ixx="6.8809E-05"
        ixy="6.4691E-05"
        ixz="-1.4066E-07"
        iyy="0.00016524"
        iyz="6.6994E-08"
        izz="0.00016991" />
    </inertial>
    <visual>
      <origin
        xyz="0 0 0"
        rpy="0 0 0" />
      <geometry>
        <mesh
          filename="package://spider/meshes/ankle_LF_link.STL" />
      </geometry>
      <material
        name="PLA">
        <color
          rgba="0.79216 0.81961 0.93333 1" />
      </material>
    </visual>
    <collision>
      <origin
        xyz="0 0 0"
        rpy="0 0 0" />
      <geometry>
        <mesh
          filename="package://spider/meshes/ankle_LF_link.STL" />
      </geometry>
    </collision>
  </link>
  <joint
    name="ankle_LF_joint"
    type="revolute">
    <origin
      xyz="0.1056 0.00078329 0"
      rpy="0 0 0" />
    <parent
      link="knee_LF_link" />
    <child
      link="ankle_LF_link" />
    <axis
      xyz="0 0 1" />
    <limit
      lower="-1.57"
      upper="1.57"
      effort="0.922"
      velocity="6.16" />
  </joint>
</robot>